Workbook

Sheet 角色卡 v0.8.1
B2: 人格 Personality | V2: Ver | X2: 0.8.1 | AA2: 技能 Skill | AS2: 技能点 | AU2: {=AW2-SUM(2^(AC6:AC12+1),2^(AF6:AF12+1),2^(AI6:AI12+1),2^(AL6:AL12+1),2^(AO6:AO12+1),2^(AR6:AR12+1),2^(AU6:AU12+1),2^(AX6:AX12+1))+56} -> 0 | AW2: =CL25 -> 0 | AZ2: 资产 Storage | BR2: 金钱 | BT2: 0 | BY2: 0 | BZ2: 0 | CB2: 体格 | CC2: =INT((J5*2+N5)/5-3) -> -3 | CD2: 威能 | CE2: =INT((N7*2+J9)/5-3) -> -3
B3: 玩家 | D3: 识别名 | J3: 总和： | L3: =SUM(J4:O9) -> 0 | AA3: 职业 | AE3: 天赋点 | BY3: 力量x体质 | BZ3: =J5+L5 -> 0 | CB3: -3 | CC3: [-1,-3]
B4: 姓名 | D4: 角色名 | J4: 力量 | L4: 体质 | N4: 耐性 | P4: 体力 | R4: 0 | T4: =CL13 -> 10 | V4: 清醒 | X4: =CL17 -> 4 | AA4: 0 | AC4: =IF(AA4="","",VLOOKUP(AA4,查询附表!$A:$B,2,0)) -> 无职 | AE4: 0 | AF4: 1 | AG4: 1 | AH4: 1 | AI4: 等级 | AK4: 0 | AM4: 经验 | AO4: 0 | AQ4: /4 | BY4: 力量x耐性 | BZ4: =J5+N5 -> 0 | CB4: -2 | CC4: [-1,-2]
B5: 性别 | D5: 男/女 | J5: 0 | L5: 0 | N5: 0 | V5: 阈值 | X5: =CL18/100 -> 0.1 | AA5: =IF(AC4="","",VLOOKUP(AC4,查询附表!$B:$D,3,0)) -> 调整数字选择职业 | AE5: =IF(OR(AA4="",AA4=0),"",VLOOKUP(AA4,查询附表!$A:$E,5,0)) | BY5: 力量x速度 | BZ5: =J5+J7 -> 0 | CB5: -1 | CC5: [0,-1]
B6: 年龄 | D6: 16-30 | J6: 速度 | L6: 魅力 | N6: 智慧 | P6: ="恢复 "&CL14 -> 恢复 1 | R6: ="防御 "&CL20 -> 防御 0 | T6: ="抗性 "&CL22&"%" -> 抗性 0% | V6: 体格 | X6: =CC2 -> -3 | AA6: 闪避 | AC6: -1 | AD6: 射击 | AF6: -1 | AG6: 爆破 | AI6: -1 | AJ6: 投掷 | AL6: -1 | AM6: 白刃 | AO6: -1 | AP6: 格斗 | AR6: -1 | AS6: 器械 | AU6: -1 | AV6: 扫射 | AX6: -1 | BY6: 力量x魅力 | BZ6: =J5+L7 -> 0 | CB6: 0 | CC6: [0,0]
B7: 身高 | D7: ???cm/?.?m | J7: 0 | L7: 0 | N7: 0 | P7: 魔力 | R7: 0 | T7: =CL15 -> 10 | V7: 威能 | X7: =CE2 -> -3 | AA7: 诈欺 | AC7: -1 | AD7: 恐吓 | AF7: -1 | AG7: 辱骂 | AI7: -1 | AJ7: 诽谤 | AL7: -1 | AM7: 取悦 | AO7: -1 | AP7: 心理 | AR7: -1 | AS7: 诅咒 | AU7: -1 | AV7: 说服 | AX7: -1 | BY7: 力量x智慧 | BZ7: =J5+N7 -> 0 | CB7: 1 | CC7: [0,+1]
B8: 体重 | D8: ???kg | J8: 灵感 | L8: 决心 | N8: 幸运 | P8: 0 | V8: 人格 | X8: 中性 | AA8: 工匠 | AC8: -1 | AD8: 运动 | AF8: -1 | AG8: 驾驶 | AI8: -1 | AJ8: 会计 | AL8: -1 | AM8: 烹饪 | AO8: -1 | AP8: 维修 | AR8: -1 | AS8: 法律 | AU8: -1 | AV8: 伪造 | AX8: -1 | BY8: 力量x灵感 | BZ8: =J5+J9 -> 0 | CB8: 2 | CC8: [0,+2]
B9: 现居 | D9: 伦敦 | J9: 0 | L9: 0 | N9: 0 | P9: ="恢复 "&CL16 -> 恢复 1 | R9: ="防御 "&CL21 -> 防御 0 | T9: ="抗性 "&CL23&"%" -> 抗性 0% | V9: 侵蚀 | X9: 0 | AA9: 化学 | AC9: -1 | AD9: 占卜 | AF9: -1 | AG9: 验尸 | AI9: -1 | AJ9: 锻造 | AL9: -1 | AM9: 绘画 | AO9: -1 | AP9: 游泳 | AR9: -1 | AS9: 历史 | AU9: -1 | AV9: 乔装 | AX9: -1 | BY9: 力量x决心 | BZ9: =J5+L9 -> 0 | CB9: 3 | CC9: [+1,+4]
AA10: 探索 | AC10: -1 | AD10: 妙手 | AF10: -1 | AG10: 工程 | AI10: -1 | AJ10: 查询 | AL10: -1 | AM10: 摄影 | AO10: -1 | AP10: 地质 | AR10: -1 | AS10: 宗教 | AU10: -1 | AV10: 药理 | AX10: -1 | BY10: 体质x耐性 | BZ10: =L5+N5 -> 0
B11: 装备 Equipment | AA11: 仪式 | AC11: -1 | AD11: 追踪 | AF11: -1 | AG11: 驯兽 | AI11: -1 | AJ11: 外语 | AL11: -1 | AM11: 娱乐 | AO11: -1 | AP11: 几何 | AR11: -1 | AS11: 星学 | AU11: -1 | AV11: 种植 | AX11: -1 | BY11: 体质x速度 | BZ11: =L5+J7 -> 0 | CC11: 内加 | CF11: 倍乘 | CI11: 外加 | CL11: 出目
AA12: 气象 | AC12: -1 | AD12: 速记 | AF12: -1 | AG12: 潜行 | AI12: -1 | AJ12: 采集 | AL12: -1 | AM12: 治疗 | AO12: -1 | AP12: 电学 | AR12: -1 | AS12: 博学 | AU12: -1 | AV12: 垂钓 | AX12: -1 | BY12: 体质x魅力 | BZ12: =L5+L7 -> 0 | CB12: 状态 | CC12: 基础 | CF12: 天赋
B13: 腕 | C13: 0 | D13: 空手 | H13: 手 | I13: 0 | N13: 手 | O13: 0 | T13: 背包 | V13: 2g | AA13: 傲慢 | AC13: =INT(SUM(AC6:AC12,2)/5) -> -1 | AD13: 嫉妒 | AF13: =INT(SUM(AF6:AF12,2)/5) -> -1 | AG13: 暴戾 | AI13: =INT(SUM(AI6:AI12,2)/5) -> -1 | AJ13: 贪食 | AL13: =INT(SUM(AL6:AL12,2)/5) -> -1 | AM13: 色欲 | AO13: =INT(SUM(AO6:AO12,2)/5) -> -1 | AP13: 抑郁 | AR13: =INT(SUM(AR6:AR12,2)/5) -> -1 | AS13: 虚荣 | AU13: =INT(SUM(AU6:AU12,2)/5) -> -1 | AV13: 偏执 | AX13: =INT(SUM(AX6:AX12,2)/5) -> -1 | BY13: 体质x智慧 | BZ13: =L5+N7 -> 0 | CB13: 体力 | CC13: =L5*2+N5+10 -> 10 | CF13: 1 | CG13: 1 | CH13: 1 | CL13: =SUM(CC13:CE13)*SUMPRODUCT(CF13,CG13,CH13)+SUM(CI13:CK13) -> 10
B14: 生物质 钝击1-3 招架1-3 | T14: 这里是名称 | X14: 1 | Y14: 0 | BY14: 体质x灵感 | BZ14: =L5+J9 -> 0 | CB14: 恢复 | CC14: =INT(L5/3)+1 -> 1 | CF14: 1 | CG14: 1 | CH14: 1 | CL14: =SUM(CC14:CE14)*SUMPRODUCT(CF14,CG14,CH14)+SUM(CI14:CK14) -> 1
AA15: 特异 Specialize | AS15: 特质点 | AU15: =AW15-SUM(AA25:AX32) -> 0 | AW15: =CL26 -> 0 | AZ15: 经历 Experience | BR15: 修正 | BY15: 体质x决心 | BZ15: =L5+L9 -> 0 | CB15: 魔力 | CC15: =N7+J9+10 -> 10 | CF15: 1 | CG15: 1 | CH15: 1 | CL15: =SUM(CC15:CE15)*SUMPRODUCT(CF15,CG15,CH15)+SUM(CI15:CK15) -> 10
BY16: 耐性x速度 | BZ16: =N5+J7 -> 0 | CB16: 恢复 | CC16: =INT(J9/3)+1 -> 1 | CF16: 1 | CG16: 1 | CH16: 1 | CL16: =SUM(CC16:CE16)*SUMPRODUCT(CF16,CG16,CH16)+SUM(CI16:CK16) -> 1
B17: 头 | C17: 0 | H17: 身 | I17: 0 | N17: 足 | O17: 0 | AA17: 阵营 | AC17: 无阵营 | AG17: 宗教 | AI17: 无信仰 | AM17: 倾向 | AO17: 无倾向 | AS17: 源质 | AU17: 无明显源质 | AZ17: 外观 Appearance | BD17: 此处应该填人物自身给别人带来的印象，可以不填 | BY17: 耐性x魅力 | BZ17: =N5+L7 -> 0 | CB17: 清醒 | CC17: =INT((L9*2+N5)/3+4) -> 4 | CF17: 1 | CG17: 1 | CH17: 1 | CL17: =SUM(CC17:CE17)*SUMPRODUCT(CF17,CG17,CH17)+SUM(CI17:CK17) -> 4
AA18: =VLOOKUP(AC17,查询附表!W1:X10,2,0) -> 请选择阵营 | AG18: =VLOOKUP(AI17,查询附表!$AC:$AD,2,0) -> 你目前不属于任何一个教会 | AM18: =VLOOKUP(AO17,查询附表!$Z1:$AA4,2,0) -> 请选择倾向 | BY18: 耐性x智慧 | BZ18: =N5+N7 -> 0 | CB18: 豁免 | CC18: =10+L9 -> 10 | CF18: 1 | CG18: 1 | CH18: 1 | CL18: =SUM(CC18:CE18)*SUMPRODUCT(CF18,CG18,CH18)+SUM(CI18:CK18) -> 10
AZ19: 性格 Disposition | BD19: 此处应该填人物自身的人格属性，可以不填 | BY19: 耐性x灵感 | BZ19: =N5+J9 -> 0 | CB19: 伤害 | CC19: 属性 | CD19: 天赋 | CI19: 装备
BY20: 耐性x决心 | BZ20: =N5+L9 -> 0 | CB20: 物防 | CC20: =INT(N5/5) -> 0 | CF20: 1 | CG20: 1 | CH20: 1 | CL20: =SUM(CC20:CE20)*SUMPRODUCT(CF20,CG20,CH20)+SUM(CI20:CK20) -> 0
B21: 饰 | C21: 0 | H21: 饰 | I21: 0 | N21: 饰 | O21: 0 | AZ21: 心系 Treasure | BD21: 此处应该填人物自身心心念念人/物，可以不填 | BY21: 速度x魅力 | BZ21: =J7+L7 -> 0 | CB21: 法防 | CC21: =INT(N7/5) -> 0 | CF21: 1 | CG21: 1 | CH21: 1 | CL21: =SUM(CC21:CE21)*SUMPRODUCT(CF21,CG21,CH21)+SUM(CI21:CK21) -> 0
BY22: 速度x智慧 | BZ22: =J7+N7 -> 0 | CB22: 物抗 | CC22: 0 | CF22: 1 | CG22: 1 | CH22: 1 | CL22: =SUM(CC22:CE22)*SUMPRODUCT(CF22,CG22,CH22)+SUM(CI22:CK22) -> 0
AZ23: 难言 Sin | BD23: 此处应该填人物自身阴暗面/伤疤/心灵的伤口，可以不填 | BY23: 速度x灵感 | BZ23: =J7+J9 -> 0 | CB23: 法抗 | CC23: 0 | CF23: 1 | CG23: 1 | CH23: 1 | CL23: =SUM(CC23:CE23)*SUMPRODUCT(CF23,CG23,CH23)+SUM(CI23:CK23) -> 0
BY24: 速度x决心 | BZ24: =J7+L9 -> 0 | CB24: 增益 | CC24: 职业 | CD24: 倾向 | CF24: 天赋 | CG24: 等级
R25: 重量 | T25: =IF(V25<=CL28*0.3,"轻快",IF(V25>=CL28,"超重",IF(V25>=CL28*0.7,"缓慢","正常"))) -> 轻快 | V25: =SUM(B13:S24,Y14:Y24) -> 0 | X25: =CL28 -> 20 | AZ25: 过去的故事 Past Stories | BD25: 此处应该填人物自身过去遭遇的事情，或是幼年的家庭环境，或是少时的学习环境，直到在听到神秘之声之前，可以不写 | BY25: 魅力x智慧 | BZ25: =L7+N7 -> 0 | CB25: 技能点 | CC25: =INT(VLOOKUP(VLOOKUP($AC$4,查询附表!$B:$C,2,0),BY2:BZ30,2,0)) -> 0 | CD25: =VLOOKUP($AO$17,BY31:CA34,2,0) -> 0 | CF25: 1 | CG25: =1 -> 1 | CH25: 1 | CL25: =INT(SUM(CC25:CE25)*SUMPRODUCT(CF25,CG25,CH25)+SUM(CI25:CK25)) -> 0
B26: 失常 Abnormality | BY26: 魅力x灵感 | BZ26: =N7+J9 -> 0 | CB26: 特质点 | CC26: =INT(VLOOKUP(VLOOKUP($AC$4,查询附表!$B:$C,2,0),BY2:BZ30,2,0)) -> 0 | CD26: =VLOOKUP($AO$17,BY31:CA34,2,0) -> 0 | CF26: 1 | CG26: =0.5 -> 0.5 | CH26: 1 | CL26: =INT(SUM(CC26:CE26)*SUMPRODUCT(CF26,CG26,CH26)+SUM(CI26:CK26)) -> 0
BY27: 魅力x决心 | BZ27: =N7+L9 -> 0 | CB27: 其他 | CM27: 0.7 | CN27: 0.3
H28: 流血 | J28: - | K28: 打击 | M28: - | N28: 突刺 | P28: - | Q28: 烧伤 | S28: - | T28: 冰冻 | V28: - | W28: 麻痹 | Y28: - | AZ28: 剧本1 | BD28: 不用管 | BY28: 智慧x灵感 | BZ28: =N7+J9 -> 0 | CB28: 负重 | CC28: =20+(J5+N5*3) -> 20 | CF28: 1 | CG28: 1 | CH28: 1 | CL28: =SUM(CC28:CE28)*SUMPRODUCT(CF28,CG28,CH28)+SUM(CI28:CK28) -> 20 | CM28: =ROUND(CL28*0.7,1) -> 14 | CN28: =ROUND(CL28*0.3,1) -> 6
H29: 窒息 | J29: - | K29: 碾压 | M29: - | N29: 拉扯 | P29: - | Q29: 酸蚀 | S29: - | T29: 冲击 | V29: - | W29: 凋亡 | Y29: - | BY29: 智慧x决心 | BZ29: =N7+L9 -> 0 | CB29: 混乱 | CC29: 20 | CF29: 1 | CG29: 1 | CH29: 1 | CL29: =SUM(CC29:CE29)*SUMPRODUCT(CF29,CG29,CH29)+SUM(CI29:CK29) -> 20
B30: 崇敬 | D30: - | E30: 悲悯 | G30: - | H30: 守护 | J30: - | K30: 管理 | M30: - | N30: 爱慕 | P30: - | Q30: 理解 | S30: - | T30: 模范 | V30: - | W30: 忠诚 | Y30: - | BY30: 灵感x决心 | BZ30: =J9+L9 -> 0 | CB30: 侵蚀 | CC30: 1 | CF30: 1 | CG30: 1 | CH30: 1 | CL30: =SUM(CC30:CE30)*SUMPRODUCT(CF30,CG30,CH30)+SUM(CI30:CK30) -> 1
B31: 谦逊 | D31: - | E31: 欣赏 | G31: - | H31: 义愤 | J31: - | K31: 广爱 | M31: - | N31: 共情 | P31: - | Q31: 冷静 | S31: - | T31: 布施 | V31: - | W31: 醒悟 | Y31: - | BY31: 无倾向 | BZ31: 0 | CA31: 0 | CB31: 理智 | CC31: =INT(L9/5+1) -> 1 | CF31: 1 | CG31: 1 | CH31: 1 | CL31: =SUM(CC31:CE31)*SUMPRODUCT(CF31,CG31,CH31)+SUM(CI31:CK31) -> 1
B32: 傲世 | D32: - | E32: 攀比 | G32: - | H32: 暴躁 | J32: - | K32: 囤积 | M32: - | N32: 放纵 | P32: - | Q32: 麻木 | S32: - | T32: 表演 | V32: - | W32: 多疑 | Y32: - | BY32: 行动倾向 | BZ32: =MAX(J5,L5,J7) -> 0 | CA32: =MIN(K5,M5,K7) -> 0
B33: 支配 | D33: - | E33: 猜忌 | G33: - | H33: 挑衅 | J33: - | K33: 市侩 | M33: - | N33: 服从 | P33: - | Q33: 疏离 | S33: - | T33: 吹嘘 | V33: - | W33: 刻板 | Y33: - | BY33: 逻辑倾向 | BZ33: =MAX(N5,N7,L9) -> 0 | CA33: =MIN(O5,O7,M9) -> 0
B34: 轻蔑 | D34: - | E34: 憎恨 | G34: - | H34: 施虐 | J34: - | K34: 渴求 | M34: - | N34: 占有 | P34: - | Q34: 自毁 | S34: - | T34: 恶意 | V34: - | W34: 背叛 | Y34: - | AA34: 扭曲 Distortion of Ego | BY34: 神秘倾向 | BZ34: =MAX(J9,L7,N9) -> 0 | CA34: =MIN(K9,M7,O9) -> 0
B35: 狂妄 | D35: - | E35: 仇嫉 | G35: - | H35: 毁坏 | J35: - | K35: 暴食 | M35: - | N35: 欢愉 | P35: - | Q35: 宿命 | S35: - | T35: 幻想 | V35: - | W35: 封闭 | Y35: -
AA36: 不定 Pendulum | AE36: 你尚未扭曲
B37: 技巧 Tech
B39: 术式 | D39: 无

Sheet 计算器
B2: 特性计算器 | N2: 商店购买计算器 | AB2: 职业查询
B3: 特性名称 | C3: 等级 | D3: 计算结果 | E3: 效果 | G3: 我不会填特性！以下是格式参照 | N3: 物品名称 | O3: 数量 | P3: 金额 | Q3: 负重 | R3: 效果 | S3: =INT(SUM(P4:P12)*10-S7*100000000-S6*1000000-S5*10000-S4*100) -> 0 | U3: 我不会填装备！以下是格式参照 | AB3: 职业名 | AC3: 职业名（下拉） | AD3: 序号 | AE3: 类型
A4: 填写全名 | B4: 撕裂 | C4: 3 | D4: =IF(B4="","",VLOOKUP(B4,查询附表!I:O,C4*2,0)) -> 9 | E4: =IF(B4="","",VLOOKUP(B4,查询附表!I:O,C4*2+1,0)) -> 施加流血前，施加流血区间+[1,3] | G4: =B4&" "&ROMAN(C4) -> 撕裂 III | L4: =D4 -> 9 | N4: 刺剑 | O4: 1 | P4: =IF(N4="","",VLOOKUP(N4,查询附表!R:U,2,0)*O4) -> 650 | Q4: =IF(N4="","",VLOOKUP(N4,查询附表!$R:$U,3,0)*O4) -> 8 | R4: =IF(N4="","",VLOOKUP(N4,查询附表!R:U,4,0)) -> [目标装备护甲时] 威力-1 [招架行动时] 威力-1 突刺2-6 [命中时] 30%施加破裂I 1-3 | S4: =INT(SUM(P4:P12)/10-S7*1000000-S6*10000-S5*100) -> 0 | U4: 手 | V4: =Q4 -> 8 | W4: =N4 -> 刺剑 | AB4: 电工 | AD4: =IF(AB4="",IF(AC4="","",VLOOKUP(AC4,查询附表!B:F,5,0)),VLOOKUP(AB4,查询附表!B:F,5,0)) -> 48 | AE4: =IF(AB4="",IF(AC4="","",VLOOKUP(AC4,查询附表!B:F,2,0)),VLOOKUP(AB4,查询附表!B:F,2,0)) -> 耐性x智慧
A5: 注意错别字 | B5: 深度伤口 | C5: 2 | D5: =IF(B5="","",VLOOKUP(B5,查询附表!I:O,C5*2,0)) -> 11 | E5: =IF(B5="","",VLOOKUP(B5,查询附表!I:O,C5*2+1,0)) -> 施加流血前，施加流血等级+2 | G5: =E4 -> 施加流血前，施加流血区间+[1,3] | N5: 软木甲 | O5: 1 | P5: =IF(N5="","",VLOOKUP(N5,查询附表!R:U,2,0)*O5) -> 750 | Q5: =IF(N5="","",VLOOKUP(N5,查询附表!$R:$U,3,0)*O5) -> 6 | R5: =IF(N5="","",VLOOKUP(N5,查询附表!R:U,4,0)) -> 物理护甲0.5 魔法护甲0.7 | S5: =INT(SUM(P4:P12)/1000-S7*10000-S6*100) -> 2 | U5: =R4 -> [目标装备护甲时] 威力-1 [招架行动时] 威力-1 突刺2-6 [命中时] 30%施加破裂I 1-3 | AB5: =IF(AB4="",IF(AC4="","",VLOOKUP(AC4,查询附表!B:F,3,0)),VLOOKUP(AB4,查询附表!B:F,3,0)) -> 工程 电学 | AC5: =IF(AB4="",IF(AC4="","",VLOOKUP(AC4,查询附表!B:F,4,0)),VLOOKUP(AB4,查询附表!B:F,4,0)) -> 电表倒转 界限突破
B6: 精准打击 | C6: 1 | D6: =IF(B6="","",VLOOKUP(B6,查询附表!I:O,C6*2,0)) -> 3 | E6: =IF(B6="","",VLOOKUP(B6,查询附表!I:O,C6*2+1,0)) -> 命中率+5% | N6: 安全帽 | O6: 1 | P6: =IF(N6="","",VLOOKUP(N6,查询附表!R:U,2,0)*O6) -> 400 | Q6: =IF(N6="","",VLOOKUP(N6,查询附表!$R:$U,3,0)*O6) -> 2 | R6: =IF(N6="","",VLOOKUP(N6,查询附表!R:U,4,0)) -> 物理护甲1 | S6: =INT(SUM(P4:P12)/100000-S7*100) -> 0
C7: 1 | D7: =IF(B7="","",VLOOKUP(B7,查询附表!I:O,C7*2,0)) | E7: =IF(B7="","",VLOOKUP(B7,查询附表!I:O,C7*2+1,0)) | N7: 生命药水 | O7: 2 | P7: =IF(N7="","",VLOOKUP(N7,查询附表!R:U,2,0)*O7) -> 100 | Q7: =IF(N7="","",VLOOKUP(N7,查询附表!$R:$U,3,0)*O7) -> 2 | R7: =IF(N7="","",VLOOKUP(N7,查询附表!R:U,4,0)) -> HP+6 HP恢复抑制 | S7: =INT(SUM(P4:P12)/10000000) -> 0
D8: =IF(B8="","",VLOOKUP(B8,查询附表!I:O,C8*2,0)) | E8: =IF(B8="","",VLOOKUP(B8,查询附表!I:O,C8*2+1,0)) | G8: 仅读取第一项作为参考 | N8: 烟雾瓶 | O8: 1 | P8: =IF(N8="","",VLOOKUP(N8,查询附表!R:U,2,0)*O8) -> 100 | Q8: =IF(N8="","",VLOOKUP(N8,查询附表!$R:$U,3,0)*O8) -> 0.1 | R8: =IF(N8="","",VLOOKUP(N8,查询附表!R:U,4,0)) -> 致盲1 | U8: 仅读取第一项作为参考
D9: =IF(B9="","",VLOOKUP(B9,查询附表!I:O,C9*2,0)) | E9: =IF(B9="","",VLOOKUP(B9,查询附表!I:O,C9*2+1,0)) | G9: 部分Teller可能会帮你填 | P9: =IF(N9="","",VLOOKUP(N9,查询附表!R:U,2,0)*O9) | Q9: =IF(N9="","",VLOOKUP(N9,查询附表!$R:$U,3,0)*O9) | R9: =IF(N9="","",VLOOKUP(N9,查询附表!R:U,4,0)) | U9: 部分Teller可能会帮你填
D10: =IF(B10="","",VLOOKUP(B10,查询附表!I:O,C10*2,0)) | E10: =IF(B10="","",VLOOKUP(B10,查询附表!I:O,C10*2+1,0)) | P10: =IF(N10="","",VLOOKUP(N10,查询附表!R:U,2,0)*O10) | Q10: =IF(N10="","",VLOOKUP(N10,查询附表!$R:$U,3,0)*O10) | R10: =IF(N10="","",VLOOKUP(N10,查询附表!R:U,4,0)) | U10: *注：不要购买复数个 目前尚未加入部位索引，请自行填写
D11: =IF(B11="","",VLOOKUP(B11,查询附表!I:O,C11*2,0)) | E11: =IF(B11="","",VLOOKUP(B11,查询附表!I:O,C11*2+1,0)) | P11: =IF(N11="","",VLOOKUP(N11,查询附表!R:U,2,0)*O11) | Q11: =IF(N11="","",VLOOKUP(N11,查询附表!$R:$U,3,0)*O11) | R11: =IF(N11="","",VLOOKUP(N11,查询附表!R:U,4,0))
D12: =IF(B12="","",VLOOKUP(B12,查询附表!I:O,C12*2,0)) | E12: =IF(B12="","",VLOOKUP(B12,查询附表!I:O,C12*2+1,0)) | P12: =IF(N12="","",VLOOKUP(N12,查询附表!R:U,2,0)*O12) | Q12: =IF(N12="","",VLOOKUP(N12,查询附表!$R:$U,3,0)*O12) | R12: =IF(N12="","",VLOOKUP(N12,查询附表!R:U,4,0))
E13: ="总和："&SUM(D4:D12) -> 总和：23 | P13: 负重： | Q13: =SUM(Q4:Q12) -> 18.1 | R13: ="总和："&IF(S7=0,,S7&"P")&IF(S6=0,,S6&"T")&IF(S5=0,,S5&"G")&IF(S4=0,,S4&"S")&IF(S3=0,,S3&"C") -> 总和：2G
B15: 特性计算器（下拉版） | N15: 商店购买计算器（下拉版）
B16: 特性名称 | C16: 等级 | D16: 计算结果 | E16: 效果 | N16: 物品名称 | O16: 数量 | P16: 金额 | Q16: 负重 | R16: 效果 | S16: =INT(SUM(P17:P25)*10-S20*100000000-S19*1000000-S18*10000-S17*100) -> 0 | U16: 我不会填背包！以下是格式参照
B17: 脑震荡 | C17: 1 | D17: =IF(B17="","",VLOOKUP(B17,查询附表!I:O,C17*2,0)) -> 4 | E17: =IF(B17="","",VLOOKUP(B17,查询附表!I:O,C17*2+1,0)) -> 施加混乱前，施加混乱等级+1 | G17: =B17&" "&ROMAN(C17) -> 脑震荡 I | L17: =D17 -> 4 | N17: 新手鱼饵 | O17: 10 | P17: =IF(N17="","",VLOOKUP(N17,查询附表!R:U,2,0)*O17) -> 100 | Q17: =IF(N17="","",VLOOKUP(N17,查询附表!R:U,3,0)*O17) -> 10 | R17: =IF(N17="","",VLOOKUP(N17,查询附表!R:U,4,0)) -> 5%渔力 | S17: =INT(SUM(P17:P25)/10-S20*1000000-S19*10000-S18*100) -> 10 | U17: =N17 -> 新手鱼饵 | Y17: =O17 -> 10 | Z17: =Q17 -> 10
B18: 新陈代谢 | C18: 1 | D18: =IF(B18="","",VLOOKUP(B18,查询附表!I:O,C18*2,0)) -> 4 | E18: =IF(B18="","",VLOOKUP(B18,查询附表!I:O,C18*2+1,0)) -> 消耗品效果33%强化 | G18: =E17 -> 施加混乱前，施加混乱等级+1 | O18: 1 | P18: =IF(N18="","",VLOOKUP(N18,查询附表!R:U,2,0)*O18) | Q18: =IF(N18="","",VLOOKUP(N18,查询附表!R:U,3,0)*O18) | R18: =IF(N18="","",VLOOKUP(N18,查询附表!R:U,4,0)) | S18: =INT(SUM(P17:P25)/1000-S20*10000-S19*100) -> 0 | U18: =N18 -> 0 | Y18: =O18 -> 1 | Z18: =Q18
D19: =IF(B19="","",VLOOKUP(B19,查询附表!I:O,C19*2,0)) | E19: =IF(B19="","",VLOOKUP(B19,查询附表!I:O,C19*2+1,0)) | O19: 25 | P19: =IF(N19="","",VLOOKUP(N19,查询附表!R:U,2,0)*O19) | Q19: =IF(N19="","",VLOOKUP(N19,查询附表!R:U,3,0)*O19) | R19: =IF(N19="","",VLOOKUP(N19,查询附表!R:U,4,0)) | S19: =INT(SUM(P17:P25)/100000-S20*100) -> 0 | U19: 仅读取前两项作为参考
D20: =IF(B20="","",VLOOKUP(B20,查询附表!I:O,C20*2,0)) | E20: =IF(B20="","",VLOOKUP(B20,查询附表!I:O,C20*2+1,0)) | O20: 2 | P20: =IF(N20="","",VLOOKUP(N20,查询附表!R:U,2,0)*O20) | Q20: =IF(N20="","",VLOOKUP(N20,查询附表!R:U,3,0)*O20) | R20: =IF(N20="","",VLOOKUP(N20,查询附表!R:U,4,0)) | S20: =INT(SUM(P17:P25)/10000000) -> 0 | U20: 部分Teller可能会帮你填
D21: =IF(B21="","",VLOOKUP(B21,查询附表!I:O,C21*2,0)) | E21: =IF(B21="","",VLOOKUP(B21,查询附表!I:O,C21*2+1,0)) | P21: =IF(N21="","",VLOOKUP(N21,查询附表!R:U,2,0)*O21) | Q21: =IF(N21="","",VLOOKUP(N21,查询附表!R:U,3,0)*O21) | R21: =IF(N21="","",VLOOKUP(N21,查询附表!R:U,4,0))
D22: =IF(B22="","",VLOOKUP(B22,查询附表!I:O,C22*2,0)) | E22: =IF(B22="","",VLOOKUP(B22,查询附表!I:O,C22*2+1,0)) | P22: =IF(N22="","",VLOOKUP(N22,查询附表!R:U,2,0)*O22) | Q22: =IF(N22="","",VLOOKUP(N22,查询附表!R:U,3,0)*O22) | R22: =IF(N22="","",VLOOKUP(N22,查询附表!R:U,4,0))
D23: =IF(B23="","",VLOOKUP(B23,查询附表!I:O,C23*2,0)) | E23: =IF(B23="","",VLOOKUP(B23,查询附表!I:O,C23*2+1,0)) | P23: =IF(N23="","",VLOOKUP(N23,查询附表!R:U,2,0)*O23) | Q23: =IF(N23="","",VLOOKUP(N23,查询附表!R:U,3,0)*O23) | R23: =IF(N23="","",VLOOKUP(N23,查询附表!R:U,4,0))
D24: =IF(B24="","",VLOOKUP(B24,查询附表!I:O,C24*2,0)) | E24: =IF(B24="","",VLOOKUP(B24,查询附表!I:O,C24*2+1,0)) | P24: =IF(N24="","",VLOOKUP(N24,查询附表!R:U,2,0)*O24) | Q24: =IF(N24="","",VLOOKUP(N24,查询附表!R:U,3,0)*O24) | R24: =IF(N24="","",VLOOKUP(N24,查询附表!R:U,4,0))
D25: =IF(B25="","",VLOOKUP(B25,查询附表!I:O,C25*2,0)) | E25: =IF(B25="","",VLOOKUP(B25,查询附表!I:O,C25*2+1,0)) | P25: =IF(N25="","",VLOOKUP(N25,查询附表!R:U,2,0)*O25) | Q25: =IF(N25="","",VLOOKUP(N25,查询附表!R:U,3,0)*O25) | R25: =IF(N25="","",VLOOKUP(N25,查询附表!R:U,4,0))
E26: ="总和："&SUM(D17:D25) -> 总和：8 | P26: 负重： | Q26: =SUM(Q17:Q25) -> 10 | R26: ="总和："&IF(S20=0,,S20&"P")&IF(S19=0,,S19&"T")&IF(S18=0,,S18&"G")&IF(S17=0,,S17&"S")&IF(S16=0,,S16&"C") -> 总和：10S

Sheet 查询附表
A1: 0 | B1: 无职 | C1: 0 | D1: 调整数字选择职业 | F1: 0 | H1: 通用 | I1: 将功补过 | J1: -3 | K1: 失去4技能点 | Q1: 烹饪 | W1: 无阵营 | X1: 请选择阵营 | Z1: 无倾向 | AA1: 请选择倾向 | AC1: 无信仰 | AD1: 你目前不属于任何一个教会 | AF1: 阵营 | AH1: 游春
A2: 1 | B2: 战士 | C2: 力量x体质 | D2: 白刃 格斗 | E2: 首当其冲 拳拳到肉 | F2: 1 | I2: 精益求精 | J2: 4 | K2: 获得3技能点 | L2: 8 | M2: 获得6技能点 | N2: 12 | O2: 获得9技能点 | R2: - | W2: 守序善良 | X2: 豁免+10 善良发生+10% | Z2: 行动倾向 | AA2: 直接，冲动，倡导简单暴力，你遵循人最原始的欲望 | AC2: One 拜辰会 | AD2: 加入条件：虔诚主义 | AF2: 主义 | AH2: 渌水
A3: 2 | B3: 工人 | C3: 力量x体质 | D3: 工程 采集 | E3: 铜墙铁壁 团结力量 | F3: 2 | I3: 深度学习 | J3: 6 | K3: 获得1通用天赋点 | Q3: 药水 | R3: 生命药水 | S3: 50 | T3: 1 | U3: HP+6 HP恢复抑制 | W3: 守序中立 | X3: 豁免+10 中立发生+10% | Z3: 逻辑倾向 | AA3: 客观，冷静，倡导面对真相，你追求事物最本质的特征 | AC3: Two 谐光会 | AD3: 加入条件：实用主义 | AF3: 宗教 | AH3: 惊蛰
A4: 3 | B4: 行医 | C4: 力量x体质 | D4: 运动 治疗 | E4: 钢筋铁骨 手术 | F4: 3 | I4: - | R4: 魔力药水 | S4: 50 | T4: 1 | U4: MP+6 MP恢复抑制 | W4: 守序邪恶 | X4: 豁免+10 敌对发生+10% | Z4: 神秘倾向 | AA4: 感性，抽象，倡导直觉象征，你认为一切无法解释都在超维面上合理 | AC4: Thie 黎明学会 | AD4: 加入条件：阵营为混乱 | AF4: 天赋 | AH4: 离鸿
A5: 4 | B5: 格斗家 | C5: 力量x耐性 | D5: 格斗 闪避 | E5: 保养 规避伤害 | F5: 4 | H5: 数值 | I5: 安心 | J5: 3 | K5: 精神恢复+15% | L5: 7 | M5: 精神恢复+30% | N5: 12 | O5: 精神恢复+45% | R5: 安定药水 | S5: 50 | T5: 1 | U5: SP+6 SP恢复抑制 | W5: 中立善良 | X5: 善良发生+10% | AC5: Four 决裁会 | AD5: 加入条件：阵营为守序 | AF5: 家族 | AH5: 清明
A6: 5 | B6: 厨师 | C6: 力量x耐性 | D6: 烹饪 速记 | E6: 口腹之欲 休养生息 | F6: 5 | I6: 遏制 | J6: 4 | K6: 考验豁免+6% | L6: 9 | M6: 考验豁免+12% | N6: 15 | O6: 考验豁免+20% | R6: 箭术药水 | S6: 250 | T6: 1 | U6: +20%射击命中率 | W6: 绝对中立 | X6: 中立发生+10% | AC6: Five 双心联会 | AD6: 加入条件：阵营为邪恶 | AF6: 疾病 | AH6: 谷雨
A7: 6 | B7: 矿工 | C7: 力量x耐性 | D7: 采集 地质 | E7: 钢筋铁骨 精炼 | F7: 6 | I7: 复习 | J7: 6 | K7: 经验+20% | L7: 13 | M7: 经验+40% | N7: 21 | O7: 经验+60% | R7: 战斗药水 | S7: 250 | T7: 1 | U7: +20%近战命中率 | W7: 中立邪恶 | X7: 敌对发生+10% | AC7: Six 太阳教会 | AD7: 加入条件：喜欢太阳（无条件） | AF7: 血统 | AH7: 明晨
A8: 7 | B8: 弄臣 | C8: 力量x速度 | D8: 取悦 妙手 | E8: 表演 把戏 | F8: 7 | I8: 富血 | J8: 3 | K8: 体力上限+17% | L8: 6 | M8: 体力上限+33% | N8: 9 | O8: 体力上限+50% | R8: 镇静药水 | S8: 250 | T8: 1 | U8: +20%精神伤害抗性 | W8: 混乱善良 | X8: 豁免-10 善良发生+10% | AC8: Seven 工人同盟会 | AD8: 加入条件：非资产家 | AF8: 境界 | AH8: 小满
A9: 8 | B9: 渔夫 | C9: 力量x速度 | D9: 气象 垂钓 | E9: 休养生息 声呐 | F9: 8 | I9: 钢铁意志 | J9: 6 | K9: SP抵抗6% | L9: 12 | M9: SP抵抗13% | N9: 18 | O9: SP抵抗20% | R9: 危险感药水 | S9: 500 | T9: 1 | U9: 灵知：危险 | W9: 混乱中立 | X9: 豁免-10 中立发生+10% | AC9: Eith 昆虫研究所 | AD9: 加入条件：实用主义 | AF9: 体格 | AH9: 芒种
A10: 9 | B10: 走私者 | C10: 力量x速度 | D10: 取悦 乔装 | E10: 多面手 夜行 | F10: 9 | I10: 规避伤害 | J10: 6 | K10: 物理近战伤害抵抗5% | L10: 12 | M10: 物理近战伤害抵抗10% | N10: 18 | O10: 物理近战伤害抵抗15% | R10: 耐力药水 | S10: 500 | T10: 1 | U10: +10%物理伤害抗性 | W10: 混乱邪恶 | X10: 豁免-10 敌对发生+10% | AC10: Nin 真实研究所 | AD10: 加入条件：唯物主义（尽管如此，他们依旧相信真眼的存在，因为他们认为真眼是一位人源神——即人造的神） | AH10: 幽居
A11: 10 | B11: 侍从 | C11: 力量x魅力 | D11: 查询 追踪 | E11: 堡垒 友善 | F11: 10 | I11: 回忆 | J11: 4 | K11: MP恢复+10% | L11: 9 | M11: MP恢复+20% | N11: 15 | O11: MP恢复+30% | R11: 钓鱼药水 | S11: 250 | T11: 1 | U11: +10%渔力 | AC11: Ten 红十字会 | AD11: 加入条件：阵营为善良 | AH11: 焦泉
A12: 11 | B12: 百夫长 | C12: 力量x魅力 | D12: 器械 诽谤 | E12: 团队信念 安抚情绪 | F12: 11 | I12: 界限突破 | J12: 8 | K12: CP出目上限+5 | L12: 17 | M12: CP出目上限+10 | N12: 27 | O12: CP出目上限+15 | R12: 鱼鳃药水 | S12: 250 | T12: 1 | U12: 肺活量提高 | AC12: Evel 谊和团 | AD12: 加入条件：阵营为守序 | AH12: 流金
A13: 12 | B13: 力士 | C13: 力量x魅力 | D13: 烹饪 药理 | E13: 口腹之欲 新陈代谢 | F13: 12 | I13: 精准打击 | J13: 3 | K13: 命中率+5% | L13: 6 | M13: 命中率+10% | N13: 9 | O13: 命中率+15% | R13: 幸运药水 | S13: 250 | T13: 1 | U13: +10%幸运 | AC13: Twel 晨眠会 | AD13: 加入条件：喜欢睡觉（无条件） | AH13: 商风
A14: 13 | B14: 探险家 | C14: 力量x智慧 | D14: 运动 探索 | E14: 寻宝 夜行 | F14: 13 | I14: 宽慰 | J14: 4 | K14: SP恢复+10% | L14: 9 | M14: SP恢复+20% | N14: 15 | O14: SP恢复+30% | R14: 爱情药水 | S14: 1200 | T14: 1 | U14: 发情 | AC14: Thir 飞行经济组织 | AD14: 加入条件：无条件，但需要定期交钱 | AH14: 处暑
A15: 14 | B15: 敲钟人 | C15: 力量x智慧 | D15: 心理 占卜 | E15: 夜行 时不我待 | F15: 14 | I15: 拳拳到肉 | J15: 4 | K15: 物理伤害+8% | L15: 8 | M15: 物理伤害+16% | N15: 12 | O15: 物理伤害+24% | R15: 铁皮药水 | S15: 250 | T15: 1 | U15: +1护甲 | AC15: For 茫雾社 | AD15: 加入条件：虔诚主义 | AH15: 白露
A16: 15 | B16: 税收官 | C16: 力量x智慧 | D16: 速记 会计 | E16: 业绩 震慑 | F16: 15 | I16: 人间烟火 | J16: 4 | K16: SP上限+10% | L16: 8 | M16: SP上限+20% | N16: 12 | O16: SP上限+30% | R16: 生命药水 | S16: 250 | T16: 1 | U16: +20%HP上限 | AC16: Fif 异象研究社 | AD16: 加入条件：实用主义 | AH16: 坐愁
A17: 16 | B17: 杀手 | C17: 力量x灵感 | D17: 白刃 诈欺 | E17: 一击致命 直击弱点 | F17: 16 | I17: 通识 | J17: 3 | K17: MP上限+10% | L17: 7 | M17: MP上限+20% | N17: 12 | O17: MP上限+30% | R17: 魔能药水 | S17: 250 | T17: 1 | U17: +20%MP上限 | AC17: Sis 异构体研究组织 | AD17: 加入条件：实用主义 | AH17: 落叶
A18: 17 | B18: 狂徒 | C18: 力量x灵感 | D18: 扫射 心理 | E18: 生生不息 傲世 | F18: 17 | I18: 铜墙铁壁 | J18: 4 | K18: 耐性+0.3 | L18: 9 | M18: 耐性+0.6 | N18: 15 | O18: 耐性+1 | R18: 魔力再生药水 | S18: 250 | T18: 1 | U18: +50%MP自然恢复 | AC18: Sev 十七研究所 | AD18: 加入条件：无条件 | AH18: 霜降
A19: 18 | B19: 窃贼 | C19: 力量x灵感 | D19: 妙手 潜行 | E19: 把戏 藏匿 | F19: 18 | I19: 外接动力 | J19: 6 | K19: CP+1 | L19: 12 | M19: CP+2 | N19: 18 | O19: CP+3 | R19: 夜视药水 | S19: 1000 | T19: 1 | U19: 灵视：夜 | AC19: Aug 机械教会 | AD19: 加入条件：唯物主义（尽管如此，他们依旧相信机构的存在，因为他们认为机构是一位人源神——即人造的神，通过机械降神的方式） | AH19: 覆霜
A20: 19 | B20: 侩子手 | C20: 力量x决心 | D20: 验尸 恐吓 | E20: 直击弱点 痛楚 | F20: 19 | I20: 休养生息 | J20: 4 | K20: 体力恢复+10% | L20: 9 | M20: 体力恢复+20% | N20: 15 | O20: 体力恢复+30% | R20: 愤怒药水 | S20: 500 | T20: 1 | U20: +10%暴击率 | AC20: Sep 月亮会 | AD20: 加入条件：女性 | AH20: 踏雪
A21: 20 | B21: 运动员 | C21: 力量x决心 | D21: 运动 追踪 | E21: 首当其冲 速战速决 | F21: 20 | I21: 正当防卫 | J21: 4 | K21: 反击率+3% | L21: 8 | M21: 反击率+6% | N21: 12 | O21: 反击率+10% | R21: 生命再生药水 | S21: 250 | T21: 1 | U21: +20%HP自然恢复 | AC21: Oct 识星会 | AD21: 加入条件：星学>1 | AH21: 凝和
A22: 21 | B22: 建筑师 | C22: 力量x决心 | D22: 工程 绘画 | E22: 富裕 匠心 | F22: 21 | I22: 直击弱点 | J22: 4 | K22: 暴击率+3% | L22: 8 | M22: 暴击率+6% | N22: 12 | O22: 暴击率+10% | R22: 敏捷药水 | S22: 250 | T22: 1 | U22: +20%速度（CP） | AC22: Nov 铭记书所 | AD22: 加入条件：无条件（如果加入该教会，则所有剧本都自带入团背景，因为这个教会会天天派人出去探索并记录世界） | AH22: 流阴
A23: 22 | B23: 园艺师 | C23: 体质x耐性 | D23: 地质 种植 | E23: 休养生息 富血 | F23: 22 | I23: - | R23: 保暖药水 | S23: 250 | T23: 1 | U23: 灵体：温暖 | AC23: Dec 黄金联会 | AD23: 加入条件：无条件，但你必须参加宗教战争 | AH23: 寒风
A24: 23 | B24: 水手 | C24: 体质x耐性 | D24: 爆破 游泳 | E24: 铜墙铁壁 水下呼吸 | F24: 23 | H24: 加成 | I24: 傲世 | J24: 4 | K24: 罪孽考验+5%，罪孽发生时，恢复5%，效果提升10% | L24: 9 | M24: 罪孽考验+10%，罪孽发生时，恢复10%，效果提升20% | N24: 16 | O24: 罪孽考验+15%，罪孽发生时，恢复15%，效果提升30% | R24: - | AC24: Jan 午夜结社 | AD24: 加入条件：无条件，但你会受到社会的偏见，如果他们知道你是这个教会的人 | AH24: 沉云
A25: 24 | B25: 投掷手 | C25: 力量x耐性 | D25: 投掷 几何 | E25: 精准打击 直击弱点 | F25: 24 | I25: 表演 | J25: 4 | K25: 减压效果+10% | L25: 8 | M25: 减压效果+20% | N25: 12 | O25: 减压效果+30% | Q25: 烟 | R25: 利群 | S25: 55 | T25: 1 | U25: 获得烟气I 2-7 失去3-9体力 | AC25: Zeth 宵寂会 | AD25: 加入条件：无条件，但你必须遵守所有教会的规则
A26: 25 | B26: 驯兽师 | C26: 体质x速度 | D26: 器械 驯兽 | E26: 调教 精准打击 | F26: 25 | I26: 裁断 | J26: 3 | K26: 伤害附加克扣0.3HP | L26: 7 | M26: 伤害附加克扣0.6HP | N26: 12 | O26: 伤害附加克扣1HP | R26: 黄金叶 | S26: 126 | T26: 1 | U26: 获得烟气II 2-7 失去2-9体力
A27: 26 | B27: 教练 | C27: 体质x速度 | D27: 说服 闪避 | E27: 一路顺风 规范动作 | F27: 26 | I27: 藏匿 | J27: 5 | K27: 仇恨-10% | L27: 10 | M27: 仇恨-20%，阻挡-1 | N27: 15 | O27: 仇恨-30%，阻挡-2 | R27: 芙蓉王 | S27: 167 | T27: 1 | U27: 获得烟气II 4-11 失去4-12体力
A28: 27 | B28: 骑手 | C28: 体质x速度 | D28: 驾驶 驯兽 | E28: 首当其冲 速战速决 | F28: 27 | I28: 冲锋陷阵 | J28: 4 | K28: 每一个敌人，获得抵抗3%，伤害+10%，最多三层 | L28: 9 | M28: 每一个敌人，获得抵抗6%，伤害+20%，最多三层 | N28: 15 | O28: 每一个敌人，获得抵抗10%，伤害+30%，最多三层 | R28: 白沙 | S28: 282 | T28: 1 | U28: 获得烟气III 1-5 失去3-9体力
A29: 28 | B29: 性工作者 | C29: 体质x魅力 | D29: 取悦 娱乐 | E29: 安心 孕体 | F29: 28 | I29: 此面向敌 | J29: 5 | K29: 在前场时，伤害+5%，抵抗+2% | L29: 10 | M29: 在前场时，伤害+10%，抵抗+4% | N29: 15 | O29: 在前场时，伤害+15%，抵抗+6% | R29: 嗅盐 | S29: 250 | T29: 1 | U29: 获得呼吸II X 消耗X嗅盐，X由自己决定，购买一份X=20
A30: 29 | B30: 神甫 | C30: 体质x魅力 | D30: 宗教 仪式 | E30: 寻找自我 傲世 | F30: 29 | I30: 电表倒转 | J30: 11 | K30: CP消耗-1 | L30: 33 | M30: CP消耗-2 | Q30: 酒 | R30: -
A31: 30 | B31: 护理 | C31: 体质x魅力 | D31: 烹饪 娱乐 | E31: 安抚情绪 安心 | F31: 30 | I31: 钢筋铁骨 | J31: 7 | K31: 减缓结算25%伤害 | L31: 15 | M31: 减缓结算50%伤害 | N31: 24 | O31: 减缓结算75%伤害 | R31: 利民 | S31: 34 | T31: 1 | U31: 获得酒精I 2-7 失去3-9魔力
A32: 31 | B32: 乐师 | C32: 体质x智慧 | D32: 取悦 速记 | E32: 呕哑 余音绕梁 | F32: 31 | I32: 规范动作 | J32: 8 | K32: 战斗投点最小值+1 | L32: 18 | M32: 战斗投点最小值+2 | R32: 红乡 | S32: 98 | T32: 1 | U32: 获得酒精II 2-7 失去2-9魔力
A33: 32 | B33: 测量员 | C33: 体质x智慧 | D33: 地质 几何 | E33: 藏匿 精准打击 | F33: 32 | I33: 口腹之欲 | J33: 4 | K33: 药物副作用免疫20% | L33: 9 | M33: 药物副作用免疫40% | N33: 16 | O33: 药物副作用免疫60% | R33: 蓝星 | S33: 145 | T33: 1 | U33: 获得酒精II 4-11 失去4-12魔力
A34: 33 | B34: 说书人 | C34: 体质x智慧 | D34: 诈欺 诽谤 | E34: 表演 谈判 | F34: 33 | I34: 狂热 | J34: 5 | K34: 每过一回合，伤害+4%，CP+1，最多三层 | L34: 11 | M34: 每过一回合，伤害+8%，CP+1.5，最多三层 | N34: 18 | O34: 每过一回合，伤害+12%，CP+2，最多三层 | R34: 清 | S34: 400 | T34: 1 | U34: 获得酒精III 2-5 失去3-8魔力
A35: 34 | B35: 赌徒 | C35: 体质x灵感 | D35: 心理 射击 | E35: 命运 狂热 | F35: 34 | I35: 良药 | J35: 4 | K35: 治疗恢复+15% | L35: 9 | M35: 治疗恢复+30% | N35: 15 | O35: 治疗恢复+45% | R35: -
A36: 35 | B36: 礼仪师 | C36: 体质x灵感 | D36: 外语 乔装 | E36: 友善 遏制 | F36: 35 | I36: 量体裁衣 | J36: 9 | K36: 你可以把超斩25%的伤害分配给另一个可命中目标 | L36: 18 | M36: 你可以把超斩50%的伤害分配给另一个可命中目标 | Q36: 杂货 | R36: 木箭矢 | S36: 6 | T36: 0.2 | U36: 打击0 [命中时] 10%施加混乱I 1-3
A37: 36 | B37: 舞者 | C37: 体质x灵感 | D37: 仪式 娱乐 | E37: 表演 名声远扬 | F37: 36 | I37: 临时护甲 | J37: 5 | K37: 战斗轮首轮耐性+1，递减1个回合 | L37: 11 | M37: 战斗轮首轮耐性+2，递减1个回合 | N37: 18 | O37: 战斗轮首轮耐性+3，递减2个回合 | R37: 钨箭矢 | S37: 8 | T37: 0.2 | U37: 流血0-1 [命中时] 10%施加流血I 1-3
A38: 37 | B38: 维修工 | C38: 体质x决心 | D38: 维修 伪造 | E38: 保养 匠心 | F38: 37 | I38: 铭记 | J38: 6 | K38: 抗性学习+10% | L38: 14 | M38: 抗性学习+20% | N38: 24 | O38: 抗性学习+30% | R38: 铁箭矢 | S38: 8 | T38: 0.2 | U38: 突刺0-1 [命中时] 10%施加破裂I 1-3
A39: 38 | B39: 装甲兵 | C39: 体质x决心 | D39: 格斗 辱骂 | E39: 此面向敌 堡垒 | F39: 38 | I39: 命运 | J39: 12 | K39: 重掷骰子 | R39: 火药 | S39: 6 | T39: 0.2 | U39: 燃烧0 10%燃烧
A40: 39 | B40: 执旗手 | C40: 体质x决心 | D40: 探索 心理 | E40: 激扬 团队信念 | F40: 39 | I40: 呕哑 | J40: 5 | K40: debuff效果+15% | L40: 10 | M40: debuff效果+30% | N40: 15 | O40: debuff效果+45% | R40: 钨弹 | S40: 20 | T40: 0.2 | U40: 0 10%流血//0 10%破裂
...

Sheet 地图
D4: Aurora Door 极光门 | V4: The Fif City 第五城
D10: Hambina 汉比纳 | P10: Jallival 加里瓦
G13: Rarin 拉林 | M13: Orraw 欧罗 | P13: Chimondo 奇蒙多
D16: Uto 乌托 | G16: Xiplut 西普露特 | J16: Sophin 索菲 | M16: London 伦敦 | P16: Mahsio 麦西欧 | V16: Zellia Lily 望冰湾 | AF16: Zellia Lily 望冰湾
D19: The Natural Sigh 绝望之地 | J19: Eurio 钨里约 | P19: Pascicar 帕希卡
V22: Natizar Port 连云港 | Z22: Natizar Port 连云港 | AF22: Anston 安斯顿 | AI22: Fullory 弗洛伊
J25: Sunshine Island 日光岛 | AI25: Wixes 威西斯 | AL25: Warld 瓦尔登 | AO25: Carnival 嘉年华 | AU25: Sulphur Ocean 硫磺海
